<?xml version="1.0"?>
<robot name="toio_style">
  <!--フットプリント-->
  <link name="base_footprint" />
  <joint name="base_joint" type="fixed">
    <origin xyz="0 0 0.126" />
    <parent link="base_footprint" />
    <child link="base_link" />
  </joint>

  <!--ボディ-->
  <link name="base_link">
    <visual>
      <geometry>
        <box size="0.3 0.3 0.23" />
      </geometry>
      <material name="white">
        <color rgba="1.0 1.0 1.0 1.0" />
      </material>
    </visual>
    <collision>
      <geometry>
        <box size="0.3 0.3 0.23" />
      </geometry>
    </collision>
    <inertial>
      <mass value="1.0" />
      <inertia ixx="0.015" iyy="0.0375" izz="0.0375" ixy="0" ixz="0" iyz="0" />
    </inertial>
  </link>

  <!--右車輪-->
  <link name="right_wheel">
    <visual>
      <geometry>
        <cylinder length="0.05" radius="0.035" />
      </geometry>
      <material name="gray">
        <color rgba="0.2 0.2 0.2 1" />
      </material>
    </visual>
    <collision>
      <geometry>
        <cylinder length="0.05" radius="0.035" />
      </geometry>
    </collision>
    <inertial>
      <mass value="0.1" />
      <inertia ixx="5.1458e-5" iyy="5.1458e-5" izz="6.125e-5" ixy="0" ixz="0" iyz="0" />
    </inertial>
  </link>
  <joint name="right_wheel_joint" type="continuous">
    <axis xyz="0 0 1" />
    <parent link="base_link" />
    <child link="right_wheel" />
    <origin rpy="-1.5708 0 0" xyz="0.0 -0.125 -.09" />
  </joint>

  <!--左車輪-->
  <link name="left_wheel">
    <visual>
      <geometry>
        <cylinder length="0.05" radius="0.035" />
      </geometry>
      <material name="gray" />
    </visual>
    <collision>
      <geometry>
        <cylinder length="0.05" radius="0.035" />
      </geometry>
    </collision>
    <inertial>
      <mass value="0.1" />
      <inertia ixx="5.1458e-5" iyy="5.1458e-5" izz="6.125e-5" ixy="0" ixz="0" iyz="0" />
    </inertial>
  </link>
  <joint name="left_wheel_joint" type="continuous">
    <axis xyz="0 0 1" />
    <parent link="base_link" />
    <child link="left_wheel" />
    <origin rpy="-1.5708 0 0" xyz="0.0 0.125 -.09" />
  </joint>

  <!--レーザースキャナー-->
  <link name="base_scan">
    <visual>
      <origin xyz="0 0 0" rpy="0 0 0" />
      <geometry>
        <box size="0.1 0.1 0.1" />
      </geometry>
    </visual>
    <collision>
      <origin xyz="0 0 0" rpy="0 0 0" />
      <geometry>
        <box size="0.1 0.1 0.1" />
      </geometry>
    </collision>
    <inertial>
      <mass value="1e-5" />
      <origin xyz="0 0 0" rpy="0 0 0" />
      <inertia ixx="1e-6" ixy="0" ixz="0" iyy="1e-6" iyz="0" izz="1e-6" />
    </inertial>
  </link>
  <joint name="scan_joint" type="fixed">
    <axis xyz="0 1 0" />
    <origin xyz="0 0 0.2" rpy="0 0 0" />
    <parent link="base_link" />
    <child link="base_scan" />
  </joint>
</robot>